<?xml version="1.0"?>
<!-- This file contains the urdf of the base platform -->
<!-- Description of the robot in URDF format -->
<!-- Each link must have at least visual for rivz -->
<!-- Each link must have inertia and collision for gazebo -->

<robot name="rmitbot" xmlns:xacro="http://ros.org/wiki/xacro">
    
    <link name="base_footprint"/>

    <link name="base_link">
        <inertial>
            <origin xyz="0 0 0.14106" rpy="0.0 0.0 0.0" />
            <mass value="204.7"/> 
            <inertia 
                ixx="3.636e+03" ixy="-1.608e-05" ixz="-3.867e-06"
                iyy="3.806e+03" iyz="-1.250e-06" 
                izz="6.563e+03" />
        </inertial>
        <visual>
            <origin xyz="0 0 -0.095" rpy="0 0 0" />
            <geometry>
                <mesh filename="package://rmitbot_description/meshes/base_link.stl" />
            </geometry>
        </visual>
        <collision>
            <origin xyz="0 0 -0.095" rpy="0 0 0" />
            <geometry>
                <mesh filename="package://rmitbot_description/meshes/base_link.stl" />
            </geometry>
        </collision>
    </link>


    <joint name="base_joint" type="fixed">
        <parent link="base_footprint"/>
        <child link="base_link" />
        <origin xyz="0 0 0.095" rpy="0 0 0"/>
    </joint>

    <link name="left_wheel1">
        <inertial>
            <origin xyz="-0.195 0.185 0.05" rpy="0 0 0" />
            <mass value="4.315763" />
            <inertia 
                ixx="5.3947033e-03" ixy="6.821e-17" ixz="-1.137e-17"
                iyy="4.4596211e-03" iyz="0.0" 
                izz="4.4596218e-03" />
        </inertial>
        <visual>
            <origin xyz="0.16 -0.185 -0.05" rpy="0 0 0" />
            <geometry>
                <mesh filename="package://rmitbot_description/meshes/left_wheel1.stl" />
            </geometry>
        </visual>
        <collision>
            <origin xyz="0.16 -0.185 -0.05" rpy="0 0 0" />
            <geometry>
                <mesh filename="package://rmitbot_description/meshes/left_wheel1.stl" />
            </geometry>
        </collision>
    </link>

    <joint name="left_wheel1_joint" type="continuous">
        <origin xyz="-0.16 0.185 -0.05" rpy="0 0 0" />
        <parent link="base_link" />
        <child link="left_wheel1" />
        <axis xyz="1 0 0" />
    </joint>

    <link name="left_wheel2">
        <inertial>
            <origin xyz="-0.195 -0.185 0.05" rpy="0 0 0" />
            <mass value="4.315763" />
            <inertia 
                ixx="0.0053947033" ixy="-2.274e-12" ixz="0.0"
                iyy="0.0044596211" iyz="0.0"
                izz="0.0044596218" />
        </inertial>
        <visual>
            <origin xyz="0.16 0.185 -0.05" rpy="0 0 0" />
            <geometry>
                <mesh filename="package://rmitbot_description/meshes/left_wheel2.stl" />
            </geometry>
        </visual>
        <collision>
            <origin xyz="0.16 0.185 -0.05" rpy="0 0 0" />
            <geometry>
                <mesh filename="package://rmitbot_description/meshes/left_wheel2.stl" />
            </geometry>
        </collision>
    </link>


    <joint name="left_wheel2_joint" type="continuous">
        <origin xyz="-0.16 -0.185 -0.05" rpy="0 0 0" />
        <parent link="base_link" />
        <child link="left_wheel2" />
        <axis xyz="1 0 0" />
    </joint>

    <link name="right_wheel1">
        <inertial>
            <origin xyz="0.195 0.185 0.05" rpy="0 0 0" />
            <mass value="4.315763" />
            <inertia 
                ixx="0.0053947033" ixy="2.274e-12" ixz="0.0"
                iyy="0.0044596211" iyz="0.0"
                izz="0.0044596218" />
        </inertial>
        <visual>
            <origin xyz="-0.16 -0.185 -0.05" rpy="0 0 0" />
            <geometry>
                <mesh filename="package://rmitbot_description/meshes/right_wheel1.stl" />
            </geometry>
        </visual>
        <collision>
            <origin xyz="-0.16 -0.185 -0.05" rpy="0 0 0" />
            <geometry>
                <mesh filename="package://rmitbot_description/meshes/right_wheel1.stl" />
            </geometry>
        </collision>
    </link>

    <joint name="right_wheel1_joint" type="continuous">
        <origin xyz="0.16 -0.185 -0.05" rpy="0 0 0" />
        <parent link="base_link" />
        <child link="right_wheel1" />
        <axis xyz="1 0 0" />
    </joint>
    
    <link name="right_wheel2">
        <inertial>
            <origin xyz="0.195 -0.185 0.05" rpy="0 0 0" />
            <mass value="4.315763" />
            <inertia 
                ixx="0.0053947033" ixy="-2.274e-12" ixz="0.0"
                iyy="0.0044596211" iyz="0.0"
                izz="0.0044596218" />
        </inertial>
        <visual>
            <origin xyz="-0.16 0.185 -0.05" rpy="0 0 0" />
            <geometry>
                <mesh filename="package://rmitbot_description/meshes/right_wheel2.stl" />
            </geometry>
        </visual>
        <collision>
            <origin xyz="-0.16 0.185 -0.05" rpy="0 0 0" />
            <geometry>
                <mesh filename="package://rmitbot_description/meshes/right_wheel2.stl" />
            </geometry>
        </collision>
    </link>


    <joint name="right_wheel2_joint" type="continuous">
        <origin xyz="0.16 0.185 -0.05" rpy="0 0 0" />
        <parent link="base_link" />
        <child link="right_wheel2" />
        <axis xyz="1 0 0" />
    </joint>
</robot>